2025-01-23 06:48:48,182 - ERROR - Threaded polling exception: A request to the Telegram API was unsuccessful. Error code: 400. Description: Bad Request: message to delete not found
2025-01-23 06:48:48,189 - ERROR - Exception traceback:
Traceback (most recent call last):
  File "/app/main.py", line 770, in mess
    bot.send_video(
  File "/usr/local/lib/python3.12/site-packages/telebot/__init__.py", line 2945, in send_video
    apihelper.send_video(
  File "/usr/local/lib/python3.12/site-packages/telebot/apihelper.py", line 839, in send_video
    return _make_request(token, method_url, params=payload, files=files, method='post')
           ^^^^^^^^^^^^^^^^^^^^^^^^^^^^^^^^^^^^^^^^^^^^^^^^^^^^^^^^^^^^^^^^^^^^^^^^^^^^
  File "/usr/local/lib/python3.12/site-packages/telebot/apihelper.py", line 168, in _make_request
    json_result = _check_result(method_name, result)
                  ^^^^^^^^^^^^^^^^^^^^^^^^^^^^^^^^^^
  File "/usr/local/lib/python3.12/site-packages/telebot/apihelper.py", line 195, in _check_result
    raise ApiTelegramException(method_name, result, result_json)
telebot.apihelper.ApiTelegramException: A request to the Telegram API was unsuccessful. Error code: 400. Description: Bad Request: failed to get HTTP URL content

During handling of the above exception, another exception occurred:

Traceback (most recent call last):
  File "/usr/local/lib/python3.12/site-packages/telebot/__init__.py", line 1235, in __threaded_polling
    self.worker_pool.raise_exceptions()
  File "/usr/local/lib/python3.12/site-packages/telebot/util.py", line 150, in raise_exceptions
    raise self.exception_info
  File "/usr/local/lib/python3.12/site-packages/telebot/util.py", line 93, in run
    task(*args, **kwargs)
  File "/usr/local/lib/python3.12/site-packages/telebot/__init__.py", line 9165, in _run_middlewares_and_handler
    result = handler['function'](message)
             ^^^^^^^^^^^^^^^^^^^^^^^^^^^^
  File "/app/main.py", line 782, in mess
    bot.delete_message(search_message.chat.id, search_message.message_id)
  File "/usr/local/lib/python3.12/site-packages/telebot/__init__.py", line 1989, in delete_message
    return apihelper.delete_message(self.token, chat_id, message_id, timeout=timeout)
           ^^^^^^^^^^^^^^^^^^^^^^^^^^^^^^^^^^^^^^^^^^^^^^^^^^^^^^^^^^^^^^^^^^^^^^^^^^
  File "/usr/local/lib/python3.12/site-packages/telebot/apihelper.py", line 1582, in delete_message
    return _make_request(token, method_url, params=payload, method='post')
           ^^^^^^^^^^^^^^^^^^^^^^^^^^^^^^^^^^^^^^^^^^^^^^^^^^^^^^^^^^^^^^^
  File "/usr/local/lib/python3.12/site-packages/telebot/apihelper.py", line 168, in _make_request
    json_result = _check_result(method_name, result)
                  ^^^^^^^^^^^^^^^^^^^^^^^^^^^^^^^^^^
  File "/usr/local/lib/python3.12/site-packages/telebot/apihelper.py", line 195, in _check_result
    raise ApiTelegramException(method_name, result, result_json)
telebot.apihelper.ApiTelegramException: A request to the Telegram API was unsuccessful. Error code: 400. Description: Bad Request: message to delete not found

2025-01-23 07:07:25,013 - ERROR - Threaded polling exception: A request to the Telegram API was unsuccessful. Error code: 400. Description: Bad Request: message to delete not found
2025-01-23 07:07:25,082 - ERROR - Exception traceback:
Traceback (most recent call last):
  File "/app/main.py", line 819, in mess
    bot.send_video(
  File "/usr/local/lib/python3.12/site-packages/telebot/__init__.py", line 2945, in send_video
    apihelper.send_video(
  File "/usr/local/lib/python3.12/site-packages/telebot/apihelper.py", line 839, in send_video
    return _make_request(token, method_url, params=payload, files=files, method='post')
           ^^^^^^^^^^^^^^^^^^^^^^^^^^^^^^^^^^^^^^^^^^^^^^^^^^^^^^^^^^^^^^^^^^^^^^^^^^^^
  File "/usr/local/lib/python3.12/site-packages/telebot/apihelper.py", line 168, in _make_request
    json_result = _check_result(method_name, result)
                  ^^^^^^^^^^^^^^^^^^^^^^^^^^^^^^^^^^
  File "/usr/local/lib/python3.12/site-packages/telebot/apihelper.py", line 195, in _check_result
    raise ApiTelegramException(method_name, result, result_json)
telebot.apihelper.ApiTelegramException: A request to the Telegram API was unsuccessful. Error code: 400. Description: Bad Request: wrong type of the web page content

During handling of the above exception, another exception occurred:

Traceback (most recent call last):
  File "/usr/local/lib/python3.12/site-packages/telebot/__init__.py", line 1235, in __threaded_polling
    self.worker_pool.raise_exceptions()
  File "/usr/local/lib/python3.12/site-packages/telebot/util.py", line 150, in raise_exceptions
    raise self.exception_info
  File "/usr/local/lib/python3.12/site-packages/telebot/util.py", line 93, in run
    task(*args, **kwargs)
  File "/usr/local/lib/python3.12/site-packages/telebot/__init__.py", line 9165, in _run_middlewares_and_handler
    result = handler['function'](message)
             ^^^^^^^^^^^^^^^^^^^^^^^^^^^^
  File "/app/main.py", line 830, in mess
    bot.delete_message(search_message.chat.id, search_message.message_id)
  File "/usr/local/lib/python3.12/site-packages/telebot/__init__.py", line 1989, in delete_message
    return apihelper.delete_message(self.token, chat_id, message_id, timeout=timeout)
           ^^^^^^^^^^^^^^^^^^^^^^^^^^^^^^^^^^^^^^^^^^^^^^^^^^^^^^^^^^^^^^^^^^^^^^^^^^
  File "/usr/local/lib/python3.12/site-packages/telebot/apihelper.py", line 1582, in delete_message
    return _make_request(token, method_url, params=payload, method='post')
           ^^^^^^^^^^^^^^^^^^^^^^^^^^^^^^^^^^^^^^^^^^^^^^^^^^^^^^^^^^^^^^^
  File "/usr/local/lib/python3.12/site-packages/telebot/apihelper.py", line 168, in _make_request
    json_result = _check_result(method_name, result)
                  ^^^^^^^^^^^^^^^^^^^^^^^^^^^^^^^^^^
  File "/usr/local/lib/python3.12/site-packages/telebot/apihelper.py", line 195, in _check_result
    raise ApiTelegramException(method_name, result, result_json)
telebot.apihelper.ApiTelegramException: A request to the Telegram API was unsuccessful. Error code: 400. Description: Bad Request: message to delete not found

2025-01-23 07:11:51,784 - ERROR - Threaded polling exception: A request to the Telegram API was unsuccessful. Error code: 400. Description: Bad Request: message to delete not found
2025-01-23 07:11:51,883 - ERROR - Exception traceback:
Traceback (most recent call last):
  File "/app/main.py", line 819, in mess
    bot.send_video(
  File "/usr/local/lib/python3.12/site-packages/telebot/__init__.py", line 2945, in send_video
    apihelper.send_video(
  File "/usr/local/lib/python3.12/site-packages/telebot/apihelper.py", line 839, in send_video
    return _make_request(token, method_url, params=payload, files=files, method='post')
           ^^^^^^^^^^^^^^^^^^^^^^^^^^^^^^^^^^^^^^^^^^^^^^^^^^^^^^^^^^^^^^^^^^^^^^^^^^^^
  File "/usr/local/lib/python3.12/site-packages/telebot/apihelper.py", line 168, in _make_request
    json_result = _check_result(method_name, result)
                  ^^^^^^^^^^^^^^^^^^^^^^^^^^^^^^^^^^
  File "/usr/local/lib/python3.12/site-packages/telebot/apihelper.py", line 195, in _check_result
    raise ApiTelegramException(method_name, result, result_json)
telebot.apihelper.ApiTelegramException: A request to the Telegram API was unsuccessful. Error code: 400. Description: Bad Request: wrong type of the web page content

During handling of the above exception, another exception occurred:

Traceback (most recent call last):
  File "/usr/local/lib/python3.12/site-packages/telebot/__init__.py", line 1235, in __threaded_polling
    self.worker_pool.raise_exceptions()
  File "/usr/local/lib/python3.12/site-packages/telebot/util.py", line 150, in raise_exceptions
    raise self.exception_info
  File "/usr/local/lib/python3.12/site-packages/telebot/util.py", line 93, in run
    task(*args, **kwargs)
  File "/usr/local/lib/python3.12/site-packages/telebot/__init__.py", line 9165, in _run_middlewares_and_handler
    result = handler['function'](message)
             ^^^^^^^^^^^^^^^^^^^^^^^^^^^^
  File "/app/main.py", line 830, in mess
    bot.delete_message(search_message.chat.id, search_message.message_id)
  File "/usr/local/lib/python3.12/site-packages/telebot/__init__.py", line 1989, in delete_message
    return apihelper.delete_message(self.token, chat_id, message_id, timeout=timeout)
           ^^^^^^^^^^^^^^^^^^^^^^^^^^^^^^^^^^^^^^^^^^^^^^^^^^^^^^^^^^^^^^^^^^^^^^^^^^
  File "/usr/local/lib/python3.12/site-packages/telebot/apihelper.py", line 1582, in delete_message
    return _make_request(token, method_url, params=payload, method='post')
           ^^^^^^^^^^^^^^^^^^^^^^^^^^^^^^^^^^^^^^^^^^^^^^^^^^^^^^^^^^^^^^^
  File "/usr/local/lib/python3.12/site-packages/telebot/apihelper.py", line 168, in _make_request
    json_result = _check_result(method_name, result)
                  ^^^^^^^^^^^^^^^^^^^^^^^^^^^^^^^^^^
  File "/usr/local/lib/python3.12/site-packages/telebot/apihelper.py", line 195, in _check_result
    raise ApiTelegramException(method_name, result, result_json)
telebot.apihelper.ApiTelegramException: A request to the Telegram API was unsuccessful. Error code: 400. Description: Bad Request: message to delete not found

2025-01-23 07:26:48,826 - ERROR - Threaded polling exception: A request to the Telegram API was unsuccessful. Error code: 400. Description: Bad Request: wrong type of the web page content
2025-01-23 07:26:48,829 - ERROR - Exception traceback:
Traceback (most recent call last):
  File "/usr/local/lib/python3.12/site-packages/telebot/__init__.py", line 1235, in __threaded_polling
    self.worker_pool.raise_exceptions()
  File "/usr/local/lib/python3.12/site-packages/telebot/util.py", line 150, in raise_exceptions
    raise self.exception_info
  File "/usr/local/lib/python3.12/site-packages/telebot/util.py", line 93, in run
    task(*args, **kwargs)
  File "/usr/local/lib/python3.12/site-packages/telebot/__init__.py", line 9165, in _run_middlewares_and_handler
    result = handler['function'](message)
             ^^^^^^^^^^^^^^^^^^^^^^^^^^^^
  File "/app/main.py", line 697, in mess
    bot.send_photo(chat_id, send['image_url'], caption=send['caption'], parse_mode="HTML",reply_to_message_id=message.message_id)
  File "/usr/local/lib/python3.12/site-packages/telebot/__init__.py", line 2299, in send_photo
    apihelper.send_photo(
  File "/usr/local/lib/python3.12/site-packages/telebot/apihelper.py", line 545, in send_photo
    return _make_request(token, method_url, params=payload, files=files, method='post')
           ^^^^^^^^^^^^^^^^^^^^^^^^^^^^^^^^^^^^^^^^^^^^^^^^^^^^^^^^^^^^^^^^^^^^^^^^^^^^
  File "/usr/local/lib/python3.12/site-packages/telebot/apihelper.py", line 168, in _make_request
    json_result = _check_result(method_name, result)
                  ^^^^^^^^^^^^^^^^^^^^^^^^^^^^^^^^^^
  File "/usr/local/lib/python3.12/site-packages/telebot/apihelper.py", line 195, in _check_result
    raise ApiTelegramException(method_name, result, result_json)
telebot.apihelper.ApiTelegramException: A request to the Telegram API was unsuccessful. Error code: 400. Description: Bad Request: wrong type of the web page content

2025-01-23 07:26:53,442 - ERROR - Threaded polling exception: A request to the Telegram API was unsuccessful. Error code: 400. Description: Bad Request: message to delete not found
2025-01-23 07:26:53,448 - ERROR - Exception traceback:
Traceback (most recent call last):
  File "/app/main.py", line 868, in mess
    bot.send_video(
  File "/usr/local/lib/python3.12/site-packages/telebot/__init__.py", line 2945, in send_video
    apihelper.send_video(
  File "/usr/local/lib/python3.12/site-packages/telebot/apihelper.py", line 839, in send_video
    return _make_request(token, method_url, params=payload, files=files, method='post')
           ^^^^^^^^^^^^^^^^^^^^^^^^^^^^^^^^^^^^^^^^^^^^^^^^^^^^^^^^^^^^^^^^^^^^^^^^^^^^
  File "/usr/local/lib/python3.12/site-packages/telebot/apihelper.py", line 168, in _make_request
    json_result = _check_result(method_name, result)
                  ^^^^^^^^^^^^^^^^^^^^^^^^^^^^^^^^^^
  File "/usr/local/lib/python3.12/site-packages/telebot/apihelper.py", line 195, in _check_result
    raise ApiTelegramException(method_name, result, result_json)
telebot.apihelper.ApiTelegramException: A request to the Telegram API was unsuccessful. Error code: 400. Description: Bad Request: invalid file HTTP URL specified: Disallowed character in URL host

During handling of the above exception, another exception occurred:

Traceback (most recent call last):
  File "/usr/local/lib/python3.12/site-packages/telebot/__init__.py", line 1235, in __threaded_polling
    self.worker_pool.raise_exceptions()
  File "/usr/local/lib/python3.12/site-packages/telebot/util.py", line 150, in raise_exceptions
    raise self.exception_info
  File "/usr/local/lib/python3.12/site-packages/telebot/util.py", line 93, in run
    task(*args, **kwargs)
  File "/usr/local/lib/python3.12/site-packages/telebot/__init__.py", line 9165, in _run_middlewares_and_handler
    result = handler['function'](message)
             ^^^^^^^^^^^^^^^^^^^^^^^^^^^^
  File "/app/main.py", line 880, in mess
    bot.delete_message(search_message.chat.id, search_message.message_id)
  File "/usr/local/lib/python3.12/site-packages/telebot/__init__.py", line 1989, in delete_message
    return apihelper.delete_message(self.token, chat_id, message_id, timeout=timeout)
           ^^^^^^^^^^^^^^^^^^^^^^^^^^^^^^^^^^^^^^^^^^^^^^^^^^^^^^^^^^^^^^^^^^^^^^^^^^
  File "/usr/local/lib/python3.12/site-packages/telebot/apihelper.py", line 1582, in delete_message
    return _make_request(token, method_url, params=payload, method='post')
           ^^^^^^^^^^^^^^^^^^^^^^^^^^^^^^^^^^^^^^^^^^^^^^^^^^^^^^^^^^^^^^^
  File "/usr/local/lib/python3.12/site-packages/telebot/apihelper.py", line 168, in _make_request
    json_result = _check_result(method_name, result)
                  ^^^^^^^^^^^^^^^^^^^^^^^^^^^^^^^^^^
  File "/usr/local/lib/python3.12/site-packages/telebot/apihelper.py", line 195, in _check_result
    raise ApiTelegramException(method_name, result, result_json)
telebot.apihelper.ApiTelegramException: A request to the Telegram API was unsuccessful. Error code: 400. Description: Bad Request: message to delete not found

2025-01-23 07:26:57,904 - ERROR - Threaded polling exception: A request to the Telegram API was unsuccessful. Error code: 400. Description: Bad Request: message to delete not found
2025-01-23 07:26:57,984 - ERROR - Exception traceback:
Traceback (most recent call last):
  File "/app/main.py", line 918, in mess
    bot.send_video(
  File "/usr/local/lib/python3.12/site-packages/telebot/__init__.py", line 2945, in send_video
    apihelper.send_video(
  File "/usr/local/lib/python3.12/site-packages/telebot/apihelper.py", line 839, in send_video
    return _make_request(token, method_url, params=payload, files=files, method='post')
           ^^^^^^^^^^^^^^^^^^^^^^^^^^^^^^^^^^^^^^^^^^^^^^^^^^^^^^^^^^^^^^^^^^^^^^^^^^^^
  File "/usr/local/lib/python3.12/site-packages/telebot/apihelper.py", line 168, in _make_request
    json_result = _check_result(method_name, result)
                  ^^^^^^^^^^^^^^^^^^^^^^^^^^^^^^^^^^
  File "/usr/local/lib/python3.12/site-packages/telebot/apihelper.py", line 195, in _check_result
    raise ApiTelegramException(method_name, result, result_json)
telebot.apihelper.ApiTelegramException: A request to the Telegram API was unsuccessful. Error code: 400. Description: Bad Request: invalid file HTTP URL specified: Disallowed character in URL host

During handling of the above exception, another exception occurred:

Traceback (most recent call last):
  File "/usr/local/lib/python3.12/site-packages/telebot/__init__.py", line 1235, in __threaded_polling
    self.worker_pool.raise_exceptions()
  File "/usr/local/lib/python3.12/site-packages/telebot/util.py", line 150, in raise_exceptions
    raise self.exception_info
  File "/usr/local/lib/python3.12/site-packages/telebot/util.py", line 93, in run
    task(*args, **kwargs)
  File "/usr/local/lib/python3.12/site-packages/telebot/__init__.py", line 9165, in _run_middlewares_and_handler
    result = handler['function'](message)
             ^^^^^^^^^^^^^^^^^^^^^^^^^^^^
  File "/app/main.py", line 929, in mess
    bot.delete_message(search_message.chat.id, search_message.message_id)
  File "/usr/local/lib/python3.12/site-packages/telebot/__init__.py", line 1989, in delete_message
    return apihelper.delete_message(self.token, chat_id, message_id, timeout=timeout)
           ^^^^^^^^^^^^^^^^^^^^^^^^^^^^^^^^^^^^^^^^^^^^^^^^^^^^^^^^^^^^^^^^^^^^^^^^^^
  File "/usr/local/lib/python3.12/site-packages/telebot/apihelper.py", line 1582, in delete_message
    return _make_request(token, method_url, params=payload, method='post')
           ^^^^^^^^^^^^^^^^^^^^^^^^^^^^^^^^^^^^^^^^^^^^^^^^^^^^^^^^^^^^^^^
  File "/usr/local/lib/python3.12/site-packages/telebot/apihelper.py", line 168, in _make_request
    json_result = _check_result(method_name, result)
                  ^^^^^^^^^^^^^^^^^^^^^^^^^^^^^^^^^^
  File "/usr/local/lib/python3.12/site-packages/telebot/apihelper.py", line 195, in _check_result
    raise ApiTelegramException(method_name, result, result_json)
telebot.apihelper.ApiTelegramException: A request to the Telegram API was unsuccessful. Error code: 400. Description: Bad Request: message to delete not found

2025-01-23 07:27:08,772 - ERROR - Threaded polling exception: A request to the Telegram API was unsuccessful. Error code: 400. Description: Bad Request: message to delete not found
2025-01-23 07:27:08,902 - ERROR - Exception traceback:
Traceback (most recent call last):
  File "/app/main.py", line 868, in mess
    bot.send_video(
  File "/usr/local/lib/python3.12/site-packages/telebot/__init__.py", line 2945, in send_video
    apihelper.send_video(
  File "/usr/local/lib/python3.12/site-packages/telebot/apihelper.py", line 839, in send_video
    return _make_request(token, method_url, params=payload, files=files, method='post')
           ^^^^^^^^^^^^^^^^^^^^^^^^^^^^^^^^^^^^^^^^^^^^^^^^^^^^^^^^^^^^^^^^^^^^^^^^^^^^
  File "/usr/local/lib/python3.12/site-packages/telebot/apihelper.py", line 168, in _make_request
    json_result = _check_result(method_name, result)
                  ^^^^^^^^^^^^^^^^^^^^^^^^^^^^^^^^^^
  File "/usr/local/lib/python3.12/site-packages/telebot/apihelper.py", line 195, in _check_result
    raise ApiTelegramException(method_name, result, result_json)
telebot.apihelper.ApiTelegramException: A request to the Telegram API was unsuccessful. Error code: 400. Description: Bad Request: invalid file HTTP URL specified: Disallowed character in URL host

During handling of the above exception, another exception occurred:

Traceback (most recent call last):
  File "/usr/local/lib/python3.12/site-packages/telebot/__init__.py", line 1235, in __threaded_polling
    self.worker_pool.raise_exceptions()
  File "/usr/local/lib/python3.12/site-packages/telebot/util.py", line 150, in raise_exceptions
    raise self.exception_info
  File "/usr/local/lib/python3.12/site-packages/telebot/util.py", line 93, in run
    task(*args, **kwargs)
  File "/usr/local/lib/python3.12/site-packages/telebot/__init__.py", line 9165, in _run_middlewares_and_handler
    result = handler['function'](message)
             ^^^^^^^^^^^^^^^^^^^^^^^^^^^^
  File "/app/main.py", line 880, in mess
    bot.delete_message(search_message.chat.id, search_message.message_id)
  File "/usr/local/lib/python3.12/site-packages/telebot/__init__.py", line 1989, in delete_message
    return apihelper.delete_message(self.token, chat_id, message_id, timeout=timeout)
           ^^^^^^^^^^^^^^^^^^^^^^^^^^^^^^^^^^^^^^^^^^^^^^^^^^^^^^^^^^^^^^^^^^^^^^^^^^
  File "/usr/local/lib/python3.12/site-packages/telebot/apihelper.py", line 1582, in delete_message
    return _make_request(token, method_url, params=payload, method='post')
           ^^^^^^^^^^^^^^^^^^^^^^^^^^^^^^^^^^^^^^^^^^^^^^^^^^^^^^^^^^^^^^^
  File "/usr/local/lib/python3.12/site-packages/telebot/apihelper.py", line 168, in _make_request
    json_result = _check_result(method_name, result)
                  ^^^^^^^^^^^^^^^^^^^^^^^^^^^^^^^^^^
  File "/usr/local/lib/python3.12/site-packages/telebot/apihelper.py", line 195, in _check_result
    raise ApiTelegramException(method_name, result, result_json)
telebot.apihelper.ApiTelegramException: A request to the Telegram API was unsuccessful. Error code: 400. Description: Bad Request: message to delete not found

2025-01-23 07:31:11,890 - ERROR - Threaded polling exception: A request to the Telegram API was unsuccessful. Error code: 400. Description: Bad Request: message to delete not found
2025-01-23 07:31:11,896 - ERROR - Exception traceback:
Traceback (most recent call last):
  File "/app/main.py", line 819, in mess
    bot.send_video(
  File "/usr/local/lib/python3.12/site-packages/telebot/__init__.py", line 2945, in send_video
    apihelper.send_video(
  File "/usr/local/lib/python3.12/site-packages/telebot/apihelper.py", line 839, in send_video
    return _make_request(token, method_url, params=payload, files=files, method='post')
           ^^^^^^^^^^^^^^^^^^^^^^^^^^^^^^^^^^^^^^^^^^^^^^^^^^^^^^^^^^^^^^^^^^^^^^^^^^^^
  File "/usr/local/lib/python3.12/site-packages/telebot/apihelper.py", line 168, in _make_request
    json_result = _check_result(method_name, result)
                  ^^^^^^^^^^^^^^^^^^^^^^^^^^^^^^^^^^
  File "/usr/local/lib/python3.12/site-packages/telebot/apihelper.py", line 195, in _check_result
    raise ApiTelegramException(method_name, result, result_json)
telebot.apihelper.ApiTelegramException: A request to the Telegram API was unsuccessful. Error code: 400. Description: Bad Request: wrong type of the web page content

During handling of the above exception, another exception occurred:

Traceback (most recent call last):
  File "/usr/local/lib/python3.12/site-packages/telebot/__init__.py", line 1235, in __threaded_polling
    self.worker_pool.raise_exceptions()
  File "/usr/local/lib/python3.12/site-packages/telebot/util.py", line 150, in raise_exceptions
    raise self.exception_info
  File "/usr/local/lib/python3.12/site-packages/telebot/util.py", line 93, in run
    task(*args, **kwargs)
  File "/usr/local/lib/python3.12/site-packages/telebot/__init__.py", line 9165, in _run_middlewares_and_handler
    result = handler['function'](message)
             ^^^^^^^^^^^^^^^^^^^^^^^^^^^^
  File "/app/main.py", line 831, in mess
    bot.delete_message(search_message.chat.id, search_message.message_id)
  File "/usr/local/lib/python3.12/site-packages/telebot/__init__.py", line 1989, in delete_message
    return apihelper.delete_message(self.token, chat_id, message_id, timeout=timeout)
           ^^^^^^^^^^^^^^^^^^^^^^^^^^^^^^^^^^^^^^^^^^^^^^^^^^^^^^^^^^^^^^^^^^^^^^^^^^
  File "/usr/local/lib/python3.12/site-packages/telebot/apihelper.py", line 1582, in delete_message
    return _make_request(token, method_url, params=payload, method='post')
           ^^^^^^^^^^^^^^^^^^^^^^^^^^^^^^^^^^^^^^^^^^^^^^^^^^^^^^^^^^^^^^^
  File "/usr/local/lib/python3.12/site-packages/telebot/apihelper.py", line 168, in _make_request
    json_result = _check_result(method_name, result)
                  ^^^^^^^^^^^^^^^^^^^^^^^^^^^^^^^^^^
  File "/usr/local/lib/python3.12/site-packages/telebot/apihelper.py", line 195, in _check_result
    raise ApiTelegramException(method_name, result, result_json)
telebot.apihelper.ApiTelegramException: A request to the Telegram API was unsuccessful. Error code: 400. Description: Bad Request: message to delete not found

